Workbook

Sheet ReadMe
B1: SAA Model – Solver benchmark of the RISKOptimizer weights
B3: Purpose
B4: This workbook re-solves the SAA optimisation with Excel's built-in Solver, using hard constraints and no simulation. Comparing the result with the RISKOptimizer weights gives a quick annual check that the optimiser has converged and that every constraint is met.
B5: Under the model's assumptions (independent returns, portfolio rebalanced to fixed weights), maximising the mean terminal portfolio value is the same as maximising the portfolio's expected return, so the two optimisations should give very similar weights.
B7: Tabs
B8: Inputs – composite expected returns, volatilities, yields and correlations; the covariance matrix is calculated from them.
B9: Strategies – for each strategy: volatility target, minimum yield and minimum/maximum weight for each composite.
B10: Benchmark – the Solver model. The yellow weight cells are changed by Solver; everything else is calculated.
B11: Comparison – paste the RISKOptimizer weights here; the tab compares them with Solver and checks every constraint (PASS / CHECK).
B12: Run_Log – record the outcome of each annual check and the explanation of any difference beyond tolerance.
B14: Colour key
B15: Blue text on yellow = input to be entered or linked by the user. Blue text = hardcoded assumption. Green text = link to another tab. Black text = formula.
... B38: The equivalence holds only if the @RISK simulation follows the assumptions above. If RISKOptimizer measures the volatility constraint from simulated paths rather than from the inputs, small differences are expected and should be explained rather than treated as errors. Because RISKOptimizer uses soft constraints, small breaches of the targets and bounds are also expected; the tolerances on the Comparison tab decide which are acceptable.

Sheet Inputs
A1: Composite inputs (same as used by @RISK)
A2: Illustrative values as at 30/11/2021 – replace with links to SAA Model, sheet MonteCarloModel (E48:G54 and C70:I76).
A4: Composite | B4: Expected return | C4: Volatility | D4: Yield
A5: Equity | B5: 0.06039 | C5: 0.135 | D5: 0.0204
A6: Bonds - DM government | B6: 0.00723 | C6: 0.042 | D6: 0.00607
A7: Bonds - other | B7: 0.03307 | C7: 0.065 | D7: 0.03816
A8: Property | B8: 0.04507 | C8: 0.116 | D8: 0.02597
A9: Gold | B9: 0.03798 | C9: 0.178 | D9: 0
A10: Hedge funds | B10: 0.01689 | C10: 0.036 | D10: 0
A11: Cash | B11: 0.0005 | C11: 0.005 | D11: 0.0005
A13: Correlation matrix
B14: Equity | C14: DM Gov | D14: Bonds other | E14: Property | F14: Gold | G14: Hedge funds | H14: Cash
A15: Equity | B15: 1 | C15: -0.01 | D15: 0.72 | E15: 0.59 | F15: 0 | G15: 0.5 | H15: -0.16
A16: DM Gov | B16: -0.01 | C16: 1 | D16: 0.3 | E16: 0.16 | F16: 0.26 | G16: -0.17 | H16: 0.04
A17: Bonds other | B17: 0.72 | C17: 0.3 | D17: 1 | E17: 0.53 | F17: 0.29 | G17: 0.47 | H17: -0.08
A18: Property | B18: 0.59 | C18: 0.16 | D18: 0.53 | E18: 1 | F18: 0.04 | G18: 0.31 | H18: -0.18
A19: Gold | B19: 0 | C19: 0.26 | D19: 0.29 | E19: 0.04 | F19: 1 | G19: 0.27 | H19: 0.08
A20: Hedge funds | B20: 0.5 | C20: -0.17 | D20: 0.47 | E20: 0.31 | F20: 0.27 | G20: 1 | H20: -0.02
A21: Cash | B21: -0.16 | C21: 0.04 | D21: -0.08 | E21: -0.18 | F21: 0.08 | G21: -0.02 | H21: 1
A22: Symmetry check (max |C - Cᵀ|) | B22: =MAX(ABS(C15-B16),ABS(D15-B17),ABS(E15-B18),ABS(F15-B19),ABS(G15-B20),ABS(H15-B21),ABS(D16-C17),ABS(E16-C18),ABS(F16-C19),ABS(G16-C20),ABS(H16-C21),ABS(E17-D18),ABS(F17-D19),ABS(G17-D20),ABS(H17-D21),ABS(F18-E19),ABS(G18-E20),ABS(H18-E21),ABS(G19-F20),ABS(H19-F21),ABS(H20-G21)) -> 0 | C22: =IF(AND(B22<0.000001,B15=1,C16=1,D17=1,E18=1,F19=1,G20=1,H21=1),"PASS","CHECK") -> PASS
A24: Covariance matrix (volatility_i × volatility_j × correlation_ij)
B25: Equity | C25: DM Gov | D25: Bonds other | E25: Property | F25: Gold | G25: Hedge funds | H25: Cash
A26: Equity | B26: =$C$5*$C$5*B15 -> 0.018225 | C26: =$C$5*$C$6*C15 -> -5.67e-05 | D26: =$C$5*$C$7*D15 -> 0.006318 | E26: =$C$5*$C$8*E15 -> 0.0092394 | F26: =$C$5*$C$9*F15 -> 0 | G26: =$C$5*$C$10*G15 -> 0.00243 | H26: =$C$5*$C$11*H15 -> -0.000108
A27: DM Gov | B27: =$C$6*$C$5*B16 -> -5.67e-05 | C27: =$C$6*$C$6*C16 -> 0.001764 | D27: =$C$6*$C$7*D16 -> 0.000819 | E27: =$C$6*$C$8*E16 -> 0.00077952 | F27: =$C$6*$C$9*F16 -> 0.00194376 | G27: =$C$6*$C$10*G16 -> -0.00025704 | H27: =$C$6*$C$11*H16 -> 8.4e-06
A28: Bonds other | B28: =$C$7*$C$5*B17 -> 0.006318 | C28: =$C$7*$C$6*C17 -> 0.000819 | D28: =$C$7*$C$7*D17 -> 0.004225 | E28: =$C$7*$C$8*E17 -> 0.0039962 | F28: =$C$7*$C$9*F17 -> 0.0033553 | G28: =$C$7*$C$10*G17 -> 0.0010998 | H28: =$C$7*$C$11*H17 -> -2.6e-05
A29: Property | B29: =$C$8*$C$5*B18 -> 0.0092394 | C29: =$C$8*$C$6*C18 -> 0.00077952 | D29: =$C$8*$C$7*D18 -> 0.0039962 | E29: =$C$8*$C$8*E18 -> 0.013456 | F29: =$C$8*$C$9*F18 -> 0.00082592 | G29: =$C$8*$C$10*G18 -> 0.00129456 | H29: =$C$8*$C$11*H18 -> -0.0001044
A30: Gold | B30: =$C$9*$C$5*B19 -> 0 | C30: =$C$9*$C$6*C19 -> 0.00194376 | D30: =$C$9*$C$7*D19 -> 0.0033553 | E30: =$C$9*$C$8*E19 -> 0.00082592 | F30: =$C$9*$C$9*F19 -> 0.031684 | G30: =$C$9*$C$10*G19 -> 0.00173016 | H30: =$C$9*$C$11*H19 -> 7.12e-05
A31: Hedge funds | B31: =$C$10*$C$5*B20 -> 0.00243 | C31: =$C$10*$C$6*C20 -> -0.00025704 | D31: =$C$10*$C$7*D20 -> 0.0010998 | E31: =$C$10*$C$8*E20 -> 0.00129456 | F31: =$C$10*$C$9*F20 -> 0.00173016 | G31: =$C$10*$C$10*G20 -> 0.001296 | H31: =$C$10*$C$11*H20 -> -3.6e-06
A32: Cash | B32: =$C$11*$C$5*B21 -> -0.000108 | C32: =$C$11*$C$6*C21 -> 8.4e-06 | D32: =$C$11*$C$7*D21 -> -2.6e-05 | E32: =$C$11*$C$8*E21 -> -0.0001044 | F32: =$C$11*$C$9*F21 -> 7.12e-05 | G32: =$C$11*$C$10*G21 -> -3.6e-06 | H32: =$C$11*$C$11*H21 -> 2.5e-05

Sheet Strategies
A1: Strategy constraints (as set in RISKOptimizer)
A2: PLACEHOLDER values – replace with each strategy's actual volatility target, minimum yield and bounds.
E3: Minimum weight | L3: Maximum weight
A4: Strategy | B4: Vol target as % of equity vol | C4: Volatility target | D4: Minimum yield | E4: Equity | F4: DM Gov | G4: Bonds other | H4: Property | I4: Gold | J4: Hedge funds | K4: Cash | L4: Equity | M4: DM Gov | N4: Bonds other | O4: Property | P4: Gold | Q4: Hedge funds | R4: Cash
A5: Defensive | B5: 0.3 | C5: =B5*Inputs!$C$5 -> 0.0405 | D5: 0 | E5: 0 | F5: 0 | G5: 0 | H5: 0 | I5: 0 | J5: 0 | K5: 0 | L5: 1 | M5: 1 | N5: 0.4 | O5: 0.1 | P5: 0.1 | Q5: 0.15 | R5: 1
A6: Cautious | B6: 0.5 | C6: =B6*Inputs!$C$5 -> 0.0675 | D6: 0 | E6: 0 | F6: 0 | G6: 0 | H6: 0 | I6: 0 | J6: 0 | K6: 0 | L6: 1 | M6: 1 | N6: 0.4 | O6: 0.1 | P6: 0.1 | Q6: 0.15 | R6: 1
A7: Balanced | B7: 0.7 | C7: =B7*Inputs!$C$5 -> 0.0945 | D7: 0 | E7: 0 | F7: 0 | G7: 0 | H7: 0 | I7: 0 | J7: 0 | K7: 0 | L7: 1 | M7: 1 | N7: 0.4 | O7: 0.1 | P7: 0.1 | Q7: 0.15 | R7: 1
A8: Growth | B8: 0.9 | C8: =B8*Inputs!$C$5 -> 0.1215 | D8: 0 | E8: 0 | F8: 0 | G8: 0 | H8: 0 | I8: 0 | J8: 0 | K8: 0 | L8: 1 | M8: 1 | N8: 0.4 | O8: 0.1 | P8: 0.1 | Q8: 0.15 | R8: 1
A9: Income | B9: 0.5 | C9: =B9*Inputs!$C$5 -> 0.0675 | D9: 0.024 | E9: 0 | F9: 0 | G9: 0 | H9: 0 | I9: 0 | J9: 0 | K9: 0 | L9: 1 | M9: 1 | N9: 0.4 | O9: 0.1 | P9: 0.1 | Q9: 0.15 | R9: 1
A10: Income Plus | B10: 0.7 | C10: =B10*Inputs!$C$5 -> 0.0945 | D10: 0.026 | E10: 0 | F10: 0 | G10: 0 | H10: 0 | I10: 0 | J10: 0 | K10: 0 | L10: 1 | M10: 1 | N10: 0.4 | O10: 0.1 | P10: 0.1 | Q10: 0.15 | R10: 1
A11: Defensive Responsible | B11: 0.3 | C11: =B11*Inputs!$C$5 -> 0.0405 | D11: 0 | E11: 0 | F11: 0 | G11: 0 | H11: 0 | I11: 0 | J11: 0 | K11: 0 | L11: 1 | M11: 1 | N11: 0.4 | O11: 0.1 | P11: 0.1 | Q11: 0.15 | R11: 1
A12: Cautious Responsible | B12: 0.5 | C12: =B12*Inputs!$C$5 -> 0.0675 | D12: 0 | E12: 0 | F12: 0 | G12: 0 | H12: 0 | I12: 0 | J12: 0 | K12: 0 | L12: 1 | M12: 1 | N12: 0.4 | O12: 0.1 | P12: 0.1 | Q12: 0.15 | R12: 1
A13: Balanced Responsible | B13: 0.7 | C13: =B13*Inputs!$C$5 -> 0.0945 | D13: 0 | E13: 0 | F13: 0 | G13: 0 | H13: 0 | I13: 0 | J13: 0 | K13: 0 | L13: 1 | M13: 1 | N13: 0.4 | O13: 0.1 | P13: 0.1 | Q13: 0.15 | R13: 1
A14: Growth Responsible | B14: 0.9 | C14: =B14*Inputs!$C$5 -> 0.1215 | D14: 0 | E14: 0 | F14: 0 | G14: 0 | H14: 0 | I14: 0 | J14: 0 | K14: 0 | L14: 1 | M14: 1 | N14: 0.4 | O14: 0.1 | P14: 0.1 | Q14: 0.15 | R14: 1
A16: Bound check: minimum must not exceed maximum | B16: =IF(SUMPRODUCT(--(E5:K14>L5:R14))=0,"PASS","CHECK") -> PASS

Sheet Benchmark
A1: Solver benchmark – maximise expected return with hard constraints
A3: Expected return | B3: =Inputs!B5 -> 0.06039 | C3: =Inputs!B6 -> 0.00723 | D3: =Inputs!B7 -> 0.03307 | E3: =Inputs!B8 -> 0.04507 | F3: =Inputs!B9 -> 0.03798 | G3: =Inputs!B10 -> 0.01689 | H3: =Inputs!B11 -> 0.0005
A4: Yield | B4: =Inputs!D5 -> 0.0204 | C4: =Inputs!D6 -> 0.00607 | D4: =Inputs!D7 -> 0.03816 | E4: =Inputs!D8 -> 0.02597 | F4: =Inputs!D9 -> 0 | G4: =Inputs!D10 -> 0 | H4: =Inputs!D11 -> 0.0005
A6: Strategy | B6: Equity | C6: DM Gov | D6: Bonds other | E6: Property | F6: Gold | G6: Hedge funds | H6: Cash | I6: Sum of weights | J6: Expected return | K6: Variance | L6: Volatility | M6: Volatility target | N6: Target variance | O6: Yield | P6: Minimum yield | Q6: Status | S6: w × Cov (Equity) | T6: w × Cov (DM Gov) | U6: w × Cov (Bonds other) | V6: w × Cov (Property) | W6: w × Cov (Gold) | X6: w × Cov (Hedge funds) | Y6: w × Cov (Cash)
A7: =Strategies!A5 -> Defensive | B7: 0.092092 | C7: 0.091628 | D7: 0.268345 | E7: 0.084495 | F7: 0.043354 | G7: 0.15 | H7: 0.270087 | I7: =SUM(B7:H7) -> 1.000001 | J7: =SUMPRODUCT(B7:H7,$B$3:$H$3) -> 0.023221394 | K7: =SUMPRODUCT(B7:H7,S7:Y7) -> 0.0016402534 | L7: =SQRT(MAX(K7,0)) -> 0.040500042 | M7: =Strategies!C5 -> 0.0405 | N7: =M7^2 -> 0.00164025 | O7: =SUMPRODUCT(B7:H7,$B$4:$H$4) -> 0.015004283 | P7: =Strategies!D5 -> 0 | Q7: =IF(AND(ABS(I7-1)<0.00001,L7<=M7+0.000001,O7>=P7-0.000001,SUMPRODUCT((B7:H7<B22:H22-0.000001)+(B7:H7>B35:H35+0.000001))=0),"OK","CHECK") -> OK | S7: =MMULT($B7:$H7,Inputs!B$26:B$32) -> 0.0044845988 | T7: =MMULT($B7:$H7,Inputs!C$26:C$32) -> 0.00049003277 | U7: =MMULT($B7:$H7,Inputs!D$26:D$32) -> 0.0024317105 | V7: =MMULT($B7:$H7,Inputs!E$26:E$32) -> 0.0033334195 | W7: =MMULT($B7:$H7,Inputs!F$26:F$32) -> 0.0028006493 | X7: =MMULT($B7:$H7,Inputs!G$26:G$32) -> 0.00087317822 | Y7: =MMULT($B7:$H7,Inputs!H$26:H$32) -> -1.5675529e-05
A8: =Strategies!A6 -> Cautious | B8: 0.220821 | C8: 0.033302 | D8: 0.4 | E8: 0.1 | F8: 0.095876 | G8: 0.15 | H8: 0 | I8: =SUM(B8:H8) -> 0.999999 | J8: =SUMPRODUCT(B8:H8,$B$3:$H$3) -> 0.037486024 | K8: =SUMPRODUCT(B8:H8,S8:Y8) -> 0.0045562412 | L8: =SQRT(MAX(K8,0)) -> 0.067499935 | M8: =Strategies!C6 -> 0.0675 | N8: =M8^2 -> 0.00455625 | O8: =SUMPRODUCT(B8:H8,$B$4:$H$4) -> 0.022567892 | P8: =Strategies!D6 -> 0 | Q8: =IF(AND(ABS(I8-1)<0.00001,L8<=M8+0.000001,O8>=P8-0.000001,SUMPRODUCT((B8:H8<B23:H23-0.000001)+(B8:H8>B36:H36+0.000001))=0),"OK","CHECK") -> OK | S8: =MMULT($B8:$H8,Inputs!B$26:B$32) -> 0.0078382145 | T8: =MMULT($B8:$H8,Inputs!C$26:C$32) -> 0.00059958011 | U8: =MMULT($B8:$H8,Inputs!D$26:D$32) -> 0.0039987042 | V8: =MMULT($B8:$H8,Inputs!E$26:E$32) -> 0.005283663 | W8: =MMULT($B8:$H8,Inputs!F$26:F$32) -> 0.0047867023 | X8: =MMULT($B8:$H8,Inputs!G$26:G$32) -> 0.0014576919 | Y8: =MMULT($B8:$H8,Inputs!H$26:H$32) -> -3.812256e-05
A9: =Strategies!A7 -> Balanced | B9: 0.51933 | C9: 0 | D9: 0.28067 | E9: 0.1 | F9: 0.1 | G9: 0 | H9: 0 | I9: =SUM(B9:H9) -> 1 | J9: =SUMPRODUCT(B9:H9,$B$3:$H$3) -> 0.048949096 | K9: =SUMPRODUCT(B9:H9,S9:Y9) -> 0.0089302509 | L9: =SQRT(MAX(K9,0)) -> 0.094500005 | M9: =Strategies!C7 -> 0.0945 | N9: =M9^2 -> 0.00893025 | O9: =SUMPRODUCT(B9:H9,$B$4:$H$4) -> 0.023901699 | P9: =Strategies!D7 -> 0 | Q9: =IF(AND(ABS(I9-1)<0.00001,L9<=M9+0.000001,O9>=P9-0.000001,SUMPRODUCT((B9:H9<B24:H24-0.000001)+(B9:H9>B37:H37+0.000001))=0),"OK","CHECK") -> OK | S9: =MMULT($B9:$H9,Inputs!B$26:B$32) -> 0.012162002 | T9: =MMULT($B9:$H9,Inputs!C$26:C$32) -> 0.00047275072 | U9: =MMULT($B9:$H9,Inputs!D$26:D$32) -> 0.0052021077 | V9: =MMULT($B9:$H9,Inputs!E$26:E$32) -> 0.0073481031 | W9: =MMULT($B9:$H9,Inputs!F$26:F$32) -> 0.0041927241 | X9: =MMULT($B9:$H9,Inputs!G$26:G$32) -> 0.0018731248 | Y9: =MMULT($B9:$H9,Inputs!H$26:H$32) -> -6.670506e-05
A10: =Strategies!A8 -> Growth | B10: 0.879874 | C10: 0 | D10: 0 | E10: 0.020126 | F10: 0.1 | G10: 0 | H10: 0 | I10: =SUM(B10:H10) -> 1 | J10: =SUMPRODUCT(B10:H10,$B$3:$H$3) -> 0.05784067 | K10: =SUMPRODUCT(B10:H10,S10:Y10) -> 0.014762243 | L10: =SQRT(MAX(K10,0)) -> 0.12149997 | M10: =Strategies!C8 -> 0.1215 | N10: =M10^2 -> 0.01476225 | O10: =SUMPRODUCT(B10:H10,$B$4:$H$4) -> 0.018472102 | P10: =Strategies!D8 -> 0 | Q10: =IF(AND(ABS(I10-1)<0.00001,L10<=M10+0.000001,O10>=P10-0.000001,SUMPRODUCT((B10:H10<B25:H25-0.000001)+(B10:H10>B38:H38+0.000001))=0),"OK","CHECK") -> OK | S10: =MMULT($B10:$H10,Inputs!B$26:B$32) -> 0.016221656 | T10: =MMULT($B10:$H10,Inputs!C$26:C$32) -> 0.00016017576 | U10: =MMULT($B10:$H10,Inputs!D$26:D$32) -> 0.0059750015 | V10: =MMULT($B10:$H10,Inputs!E$26:E$32) -> 0.0084829153 | W10: =MMULT($B10:$H10,Inputs!F$26:F$32) -> 0.0031850225 | X10: =MMULT($B10:$H10,Inputs!G$26:G$32) -> 0.0023371641 | Y10: =MMULT($B10:$H10,Inputs!H$26:H$32) -> -9.0007546e-05
A11: =Strategies!A9 -> Income | B11: 0.251061 | C11: 0.167605 | D11: 0.4 | E11: 0.1 | F11: 0.057055 | G11: 0.02428 | H11: 0 | I11: =SUM(B11:H11) -> 1.000001 | J11: =SUMPRODUCT(B11:H11,$B$3:$H$3) -> 0.036685396 | K11: =SUMPRODUCT(B11:H11,S11:Y11) -> 0.0045562563 | L11: =SQRT(MAX(K11,0)) -> 0.067500047 | M11: =Strategies!C9 -> 0.0675 | N11: =M11^2 -> 0.00455625 | O11: =SUMPRODUCT(B11:H11,$B$4:$H$4) -> 0.024000007 | P11: =Strategies!D9 -> 0.024 | Q11: =IF(AND(ABS(I11-1)<0.00001,L11<=M11+0.000001,O11>=P11-0.000001,SUMPRODUCT((B11:H11<B26:H26-0.000001)+(B11:H11>B39:H39+0.000001))=0),"OK","CHECK") -> OK | S11: =MMULT($B11:$H11,Inputs!B$26:B$32) -> 0.0080762239 | T11: =MMULT($B11:$H11,Inputs!C$26:C$32) -> 0.00079163236 | U11: =MMULT($B11:$H11,Inputs!D$26:D$32) -> 0.0040312317 | V11: =MMULT($B11:$H11,Inputs!E$26:E$32) -> 0.0054729392 | W11: =MMULT($B11:$H11,Inputs!F$26:F$32) -> 0.0036002348 | X11: =MMULT($B11:$H11,Inputs!G$26:G$32) -> 0.0012665542 | Y11: =MMULT($B11:$H11,Inputs!H$26:H$32) -> -4.2571798e-05
A12: =Strategies!A10 -> Income Plus | B12: 0.507396 | C12: 0 | D12: 0.342037 | E12: 0.1 | F12: 0.050567 | G12: 0 | H12: 0 | I12: =SUM(B12:H12) -> 1 | J12: =SUMPRODUCT(B12:H12,$B$3:$H$3) -> 0.048380343 | K12: =SUMPRODUCT(B12:H12,S12:Y12) -> 0.0089302452 | L12: =SQRT(MAX(K12,0)) -> 0.094499974 | M12: =Strategies!C10 -> 0.0945 | N12: =M12^2 -> 0.00893025 | O12: =SUMPRODUCT(B12:H12,$B$4:$H$4) -> 0.02600001 | P12: =Strategies!D10 -> 0.026 | Q12: =IF(AND(ABS(I12-1)<0.00001,L12<=M12+0.000001,O12>=P12-0.000001,SUMPRODUCT((B12:H12<B27:H27-0.000001)+(B12:H12>B40:H40+0.000001))=0),"OK","CHECK") -> OK | S12: =MMULT($B12:$H12,Inputs!B$26:B$32) -> 0.012332222 | T12: =MMULT($B12:$H12,Inputs!C$26:C$32) -> 0.00042760106 | U12: =MMULT($B12:$H12,Inputs!D$26:D$32) -> 0.0052201217 | V12: =MMULT($B12:$H12,Inputs!E$26:E$32) -> 0.0074422472 | W12: =MMULT($B12:$H12,Inputs!F$26:F$32) -> 0.0028323936 | X12: =MMULT($B12:$H12,Inputs!G$26:G$32) -> 0.0018260896 | Y12: =MMULT($B12:$H12,Inputs!H$26:H$32) -> -7.053136e-05
A13: =Strategies!A11 -> Defensive Responsible | B13: 0.092092 | C13: 0.091628 | D13: 0.268345 | E13: 0.084495 | F13: 0.043354 | G13: 0.15 | H13: 0.270087 | I13: =SUM(B13:H13) -> 1.000001 | J13: =SUMPRODUCT(B13:H13,$B$3:$H$3) -> 0.023221394 | K13: =SUMPRODUCT(B13:H13,S13:Y13) -> 0.0016402534 | L13: =SQRT(MAX(K13,0)) -> 0.040500042 | M13: =Strategies!C11 -> 0.0405 | N13: =M13^2 -> 0.00164025 | O13: =SUMPRODUCT(B13:H13,$B$4:$H$4) -> 0.015004283 | P13: =Strategies!D11 -> 0 | Q13: =IF(AND(ABS(I13-1)<0.00001,L13<=M13+0.000001,O13>=P13-0.000001,SUMPRODUCT((B13:H13<B28:H28-0.000001)+(B13:H13>B41:H41+0.000001))=0),"OK","CHECK") -> OK | S13: =MMULT($B13:$H13,Inputs!B$26:B$32) -> 0.0044845988 | T13: =MMULT($B13:$H13,Inputs!C$26:C$32) -> 0.00049003277 | U13: =MMULT($B13:$H13,Inputs!D$26:D$32) -> 0.0024317105 | V13: =MMULT($B13:$H13,Inputs!E$26:E$32) -> 0.0033334195 | W13: =MMULT($B13:$H13,Inputs!F$26:F$32) -> 0.0028006493 | X13: =MMULT($B13:$H13,Inputs!G$26:G$32) -> 0.00087317822 | Y13: =MMULT($B13:$H13,Inputs!H$26:H$32) -> -1.5675529e-05
A14: =Strategies!A12 -> Cautious Responsible | B14: 0.220821 | C14: 0.033302 | D14: 0.4 | E14: 0.1 | F14: 0.095876 | G14: 0.15 | H14: 0 | I14: =SUM(B14:H14) -> 0.999999 | J14: =SUMPRODUCT(B14:H14,$B$3:$H$3) -> 0.037486024 | K14: =SUMPRODUCT(B14:H14,S14:Y14) -> 0.0045562412 | L14: =SQRT(MAX(K14,0)) -> 0.067499935 | M14: =Strategies!C12 -> 0.0675 | N14: =M14^2 -> 0.00455625 | O14: =SUMPRODUCT(B14:H14,$B$4:$H$4) -> 0.022567892 | P14: =Strategies!D12 -> 0 | Q14: =IF(AND(ABS(I14-1)<0.00001,L14<=M14+0.000001,O14>=P14-0.000001,SUMPRODUCT((B14:H14<B29:H29-0.000001)+(B14:H14>B42:H42+0.000001))=0),"OK","CHECK") -> OK | S14: =MMULT($B14:$H14,Inputs!B$26:B$32) -> 0.0078382145 | T14: =MMULT($B14:$H14,Inputs!C$26:C$32) -> 0.00059958011 | U14: =MMULT($B14:$H14,Inputs!D$26:D$32) -> 0.0039987042 | V14: =MMULT($B14:$H14,Inputs!E$26:E$32) -> 0.005283663 | W14: =MMULT($B14:$H14,Inputs!F$26:F$32) -> 0.0047867023 | X14: =MMULT($B14:$H14,Inputs!G$26:G$32) -> 0.0014576919 | Y14: =MMULT($B14:$H14,Inputs!H$26:H$32) -> -3.812256e-05
A15: =Strategies!A13 -> Balanced Responsible | B15: 0.51933 | C15: 0 | D15: 0.28067 | E15: 0.1 | F15: 0.1 | G15: 0 | H15: 0 | I15: =SUM(B15:H15) -> 1 | J15: =SUMPRODUCT(B15:H15,$B$3:$H$3) -> 0.048949096 | K15: =SUMPRODUCT(B15:H15,S15:Y15) -> 0.0089302509 | L15: =SQRT(MAX(K15,0)) -> 0.094500005 | M15: =Strategies!C13 -> 0.0945 | N15: =M15^2 -> 0.00893025 | O15: =SUMPRODUCT(B15:H15,$B$4:$H$4) -> 0.023901699 | P15: =Strategies!D13 -> 0 | Q15: =IF(AND(ABS(I15-1)<0.00001,L15<=M15+0.000001,O15>=P15-0.000001,SUMPRODUCT((B15:H15<B30:H30-0.000001)+(B15:H15>B43:H43+0.000001))=0),"OK","CHECK") -> OK | S15: =MMULT($B15:$H15,Inputs!B$26:B$32) -> 0.012162002 | T15: =MMULT($B15:$H15,Inputs!C$26:C$32) -> 0.00047275072 | U15: =MMULT($B15:$H15,Inputs!D$26:D$32) -> 0.0052021077 | V15: =MMULT($B15:$H15,Inputs!E$26:E$32) -> 0.0073481031 | W15: =MMULT($B15:$H15,Inputs!F$26:F$32) -> 0.0041927241 | X15: =MMULT($B15:$H15,Inputs!G$26:G$32) -> 0.0018731248 | Y15: =MMULT($B15:$H15,Inputs!H$26:H$32) -> -6.670506e-05
A16: =Strategies!A14 -> Growth Responsible | B16: 0.879874 | C16: 0 | D16: 0 | E16: 0.020126 | F16: 0.1 | G16: 0 | H16: 0 | I16: =SUM(B16:H16) -> 1 | J16: =SUMPRODUCT(B16:H16,$B$3:$H$3) -> 0.05784067 | K16: =SUMPRODUCT(B16:H16,S16:Y16) -> 0.014762243 | L16: =SQRT(MAX(K16,0)) -> 0.12149997 | M16: =Strategies!C14 -> 0.1215 | N16: =M16^2 -> 0.01476225 | O16: =SUMPRODUCT(B16:H16,$B$4:$H$4) -> 0.018472102 | P16: =Strategies!D14 -> 0 | Q16: =IF(AND(ABS(I16-1)<0.00001,L16<=M16+0.000001,O16>=P16-0.000001,SUMPRODUCT((B16:H16<B31:H31-0.000001)+(B16:H16>B44:H44+0.000001))=0),"OK","CHECK") -> OK | S16: =MMULT($B16:$H16,Inputs!B$26:B$32) -> 0.016221656 | T16: =MMULT($B16:$H16,Inputs!C$26:C$32) -> 0.00016017576 | U16: =MMULT($B16:$H16,Inputs!D$26:D$32) -> 0.0059750015 | V16: =MMULT($B16:$H16,Inputs!E$26:E$32) -> 0.0084829153 | W16: =MMULT($B16:$H16,Inputs!F$26:F$32) -> 0.0031850225 | X16: =MMULT($B16:$H16,Inputs!G$26:G$32) -> 0.0023371641 | Y16: =MMULT($B16:$H16,Inputs!H$26:H$32) -> -9.0007546e-05
I18: Solver objective (maximise) | J18: =SUM(J7:J16) -> 0.4200601
A19: Variance in column K is w × Cov × wᵀ, built with MMULT in the grey helper columns S:Y. The weight cells B7:H16 are pre-solved for the illustrative inputs; re-run Solver after updating Inputs or Strategies.
A21: Minimum weights (linked from Strategies) | B21: Equity | C21: DM Gov | D21: Bonds other | E21: Property | F21: Gold | G21: Hedge funds | H21: Cash
A22: =Strategies!A5 -> Defensive | B22: =Strategies!E5 -> 0 | C22: =Strategies!F5 -> 0 | D22: =Strategies!G5 -> 0 | E22: =Strategies!H5 -> 0 | F22: =Strategies!I5 -> 0 | G22: =Strategies!J5 -> 0 | H22: =Strategies!K5 -> 0
A23: =Strategies!A6 -> Cautious | B23: =Strategies!E6 -> 0 | C23: =Strategies!F6 -> 0 | D23: =Strategies!G6 -> 0 | E23: =Strategies!H6 -> 0 | F23: =Strategies!I6 -> 0 | G23: =Strategies!J6 -> 0 | H23: =Strategies!K6 -> 0
A24: =Strategies!A7 -> Balanced | B24: =Strategies!E7 -> 0 | C24: =Strategies!F7 -> 0 | D24: =Strategies!G7 -> 0 | E24: =Strategies!H7 -> 0 | F24: =Strategies!I7 -> 0 | G24: =Strategies!J7 -> 0 | H24: =Strategies!K7 -> 0
A25: =Strategies!A8 -> Growth | B25: =Strategies!E8 -> 0 | C25: =Strategies!F8 -> 0 | D25: =Strategies!G8 -> 0 | E25: =Strategies!H8 -> 0 | F25: =Strategies!I8 -> 0 | G25: =Strategies!J8 -> 0 | H25: =Strategies!K8 -> 0
A26: =Strategies!A9 -> Income | B26: =Strategies!E9 -> 0 | C26: =Strategies!F9 -> 0 | D26: =Strategies!G9 -> 0 | E26: =Strategies!H9 -> 0 | F26: =Strategies!I9 -> 0 | G26: =Strategies!J9 -> 0 | H26: =Strategies!K9 -> 0
A27: =Strategies!A10 -> Income Plus | B27: =Strategies!E10 -> 0 | C27: =Strategies!F10 -> 0 | D27: =Strategies!G10 -> 0 | E27: =Strategies!H10 -> 0 | F27: =Strategies!I10 -> 0 | G27: =Strategies!J10 -> 0 | H27: =Strategies!K10 -> 0
A28: =Strategies!A11 -> Defensive Responsible | B28: =Strategies!E11 -> 0 | C28: =Strategies!F11 -> 0 | D28: =Strategies!G11 -> 0 | E28: =Strategies!H11 -> 0 | F28: =Strategies!I11 -> 0 | G28: =Strategies!J11 -> 0 | H28: =Strategies!K11 -> 0
A29: =Strategies!A12 -> Cautious Responsible | B29: =Strategies!E12 -> 0 | C29: =Strategies!F12 -> 0 | D29: =Strategies!G12 -> 0 | E29: =Strategies!H12 -> 0 | F29: =Strategies!I12 -> 0 | G29: =Strategies!J12 -> 0 | H29: =Strategies!K12 -> 0
A30: =Strategies!A13 -> Balanced Responsible | B30: =Strategies!E13 -> 0 | C30: =Strategies!F13 -> 0 | D30: =Strategies!G13 -> 0 | E30: =Strategies!H13 -> 0 | F30: =Strategies!I13 -> 0 | G30: =Strategies!J13 -> 0 | H30: =Strategies!K13 -> 0
A31: =Strategies!A14 -> Growth Responsible | B31: =Strategies!E14 -> 0 | C31: =Strategies!F14 -> 0 | D31: =Strategies!G14 -> 0 | E31: =Strategies!H14 -> 0 | F31: =Strategies!I14 -> 0 | G31: =Strategies!J14 -> 0 | H31: =Strategies!K14 -> 0
A34: Maximum weights (linked from Strategies) | B34: Equity | C34: DM Gov | D34: Bonds other | E34: Property | F34: Gold | G34: Hedge funds | H34: Cash
A35: =Strategies!A5 -> Defensive | B35: =Strategies!L5 -> 1 | C35: =Strategies!M5 -> 1 | D35: =Strategies!N5 -> 0.4 | E35: =Strategies!O5 -> 0.1 | F35: =Strategies!P5 -> 0.1 | G35: =Strategies!Q5 -> 0.15 | H35: =Strategies!R5 -> 1
A36: =Strategies!A6 -> Cautious | B36: =Strategies!L6 -> 1 | C36: =Strategies!M6 -> 1 | D36: =Strategies!N6 -> 0.4 | E36: =Strategies!O6 -> 0.1 | F36: =Strategies!P6 -> 0.1 | G36: =Strategies!Q6 -> 0.15 | H36: =Strategies!R6 -> 1
A37: =Strategies!A7 -> Balanced | B37: =Strategies!L7 -> 1 | C37: =Strategies!M7 -> 1 | D37: =Strategies!N7 -> 0.4 | E37: =Strategies!O7 -> 0.1 | F37: =Strategies!P7 -> 0.1 | G37: =Strategies!Q7 -> 0.15 | H37: =Strategies!R7 -> 1
A38: =Strategies!A8 -> Growth | B38: =Strategies!L8 -> 1 | C38: =Strategies!M8 -> 1 | D38: =Strategies!N8 -> 0.4 | E38: =Strategies!O8 -> 0.1 | F38: =Strategies!P8 -> 0.1 | G38: =Strategies!Q8 -> 0.15 | H38: =Strategies!R8 -> 1
A39: =Strategies!A9 -> Income | B39: =Strategies!L9 -> 1 | C39: =Strategies!M9 -> 1 | D39: =Strategies!N9 -> 0.4 | E39: =Strategies!O9 -> 0.1 | F39: =Strategies!P9 -> 0.1 | G39: =Strategies!Q9 -> 0.15 | H39: =Strategies!R9 -> 1
A40: =Strategies!A10 -> Income Plus | B40: =Strategies!L10 -> 1 | C40: =Strategies!M10 -> 1 | D40: =Strategies!N10 -> 0.4 | E40: =Strategies!O10 -> 0.1 | F40: =Strategies!P10 -> 0.1 | G40: =Strategies!Q10 -> 0.15 | H40: =Strategies!R10 -> 1
A41: =Strategies!A11 -> Defensive Responsible | B41: =Strategies!L11 -> 1 | C41: =Strategies!M11 -> 1 | D41: =Strategies!N11 -> 0.4 | E41: =Strategies!O11 -> 0.1 | F41: =Strategies!P11 -> 0.1 | G41: =Strategies!Q11 -> 0.15 | H41: =Strategies!R11 -> 1
A42: =Strategies!A12 -> Cautious Responsible | B42: =Strategies!L12 -> 1 | C42: =Strategies!M12 -> 1 | D42: =Strategies!N12 -> 0.4 | E42: =Strategies!O12 -> 0.1 | F42: =Strategies!P12 -> 0.1 | G42: =Strategies!Q12 -> 0.15 | H42: =Strategies!R12 -> 1
A43: =Strategies!A13 -> Balanced Responsible | B43: =Strategies!L13 -> 1 | C43: =Strategies!M13 -> 1 | D43: =Strategies!N13 -> 0.4 | E43: =Strategies!O13 -> 0.1 | F43: =Strategies!P13 -> 0.1 | G43: =Strategies!Q13 -> 0.15 | H43: =Strategies!R13 -> 1
A44: =Strategies!A14 -> Growth Responsible | B44: =Strategies!L14 -> 1 | C44: =Strategies!M14 -> 1 | D44: =Strategies!N14 -> 0.4 | E44: =Strategies!O14 -> 0.1 | F44: =Strategies!P14 -> 0.1 | G44: =Strategies!Q14 -> 0.15 | H44: =Strategies!R14 -> 1

Sheet Comparison
A1: Comparison of RISKOptimizer weights with the Solver benchmark
A2: Paste the final RISKOptimizer weights (as values, in %) into the yellow cells B7:H16. Rows left blank show n/a.
J3: Tolerances
J4: Weight difference vs Solver (per composite) | M4: 0.01
J5: Expected return difference vs Solver | M5: 0.0005
J6: Volatility difference vs Solver | M6: 0.0005
J7: Bound breach | M7: 0.001
J8: Volatility above target | M8: 0.0005
J9: Yield below minimum | M9: 0.0002
A12: 1. RISKOptimizer weights and characteristics
A13: Strategy | B13: Equity | C13: DM Gov | D13: Bonds other | E13: Property | F13: Gold | G13: Hedge funds | H13: Cash | I13: Sum of weights | J13: Expected return | K13: Volatility | L13: Yield | S13: w × Cov (Equity) | T13: w × Cov (DM Gov) | U13: w × Cov (Bonds other) | V13: w × Cov (Property) | W13: w × Cov (Gold) | X13: w × Cov (Hedge funds) | Y13: w × Cov (Cash)
A14: =Strategies!A5 -> Defensive | I14: =IF(COUNT(B14:H14)=0,"n/a",SUM(B14:H14)) -> n/a | J14: =IF(COUNT(B14:H14)=0,"n/a",SUMPRODUCT(B14:H14,Benchmark!$B$3:$H$3)) -> n/a | K14: =IF(COUNT(B14:H14)=0,"n/a",SQRT(MAX(SUMPRODUCT(B14:H14,S14:Y14),0))) -> n/a | L14: =IF(COUNT(B14:H14)=0,"n/a",SUMPRODUCT(B14:H14,Benchmark!$B$4:$H$4)) -> n/a | S14: =IF(COUNT($B14:$H14)=0,0,MMULT($B14:$H14,Inputs!B$26:B$32)) -> 0 | T14: =IF(COUNT($B14:$H14)=0,0,MMULT($B14:$H14,Inputs!C$26:C$32)) -> 0 | U14: =IF(COUNT($B14:$H14)=0,0,MMULT($B14:$H14,Inputs!D$26:D$32)) -> 0 | V14: =IF(COUNT($B14:$H14)=0,0,MMULT($B14:$H14,Inputs!E$26:E$32)) -> 0 | W14: =IF(COUNT($B14:$H14)=0,0,MMULT($B14:$H14,Inputs!F$26:F$32)) -> 0 | X14: =IF(COUNT($B14:$H14)=0,0,MMULT($B14:$H14,Inputs!G$26:G$32)) -> 0 | Y14: =IF(COUNT($B14:$H14)=0,0,MMULT($B14:$H14,Inputs!H$26:H$32)) -> 0
A15: =Strategies!A6 -> Cautious | I15: =IF(COUNT(B15:H15)=0,"n/a",SUM(B15:H15)) -> n/a | J15: =IF(COUNT(B15:H15)=0,"n/a",SUMPRODUCT(B15:H15,Benchmark!$B$3:$H$3)) -> n/a | K15: =IF(COUNT(B15:H15)=0,"n/a",SQRT(MAX(SUMPRODUCT(B15:H15,S15:Y15),0))) -> n/a | L15: =IF(COUNT(B15:H15)=0,"n/a",SUMPRODUCT(B15:H15,Benchmark!$B$4:$H$4)) -> n/a | S15: =IF(COUNT($B15:$H15)=0,0,MMULT($B15:$H15,Inputs!B$26:B$32)) -> 0 | T15: =IF(COUNT($B15:$H15)=0,0,MMULT($B15:$H15,Inputs!C$26:C$32)) -> 0 | U15: =IF(COUNT($B15:$H15)=0,0,MMULT($B15:$H15,Inputs!D$26:D$32)) -> 0 | V15: =IF(COUNT($B15:$H15)=0,0,MMULT($B15:$H15,Inputs!E$26:E$32)) -> 0 | W15: =IF(COUNT($B15:$H15)=0,0,MMULT($B15:$H15,Inputs!F$26:F$32)) -> 0 | X15: =IF(COUNT($B15:$H15)=0,0,MMULT($B15:$H15,Inputs!G$26:G$32)) -> 0 | Y15: =IF(COUNT($B15:$H15)=0,0,MMULT($B15:$H15,Inputs!H$26:H$32)) -> 0
A16: =Strategies!A7 -> Balanced | I16: =IF(COUNT(B16:H16)=0,"n/a",SUM(B16:H16)) -> n/a | J16: =IF(COUNT(B16:H16)=0,"n/a",SUMPRODUCT(B16:H16,Benchmark!$B$3:$H$3)) -> n/a | K16: =IF(COUNT(B16:H16)=0,"n/a",SQRT(MAX(SUMPRODUCT(B16:H16,S16:Y16),0))) -> n/a | L16: =IF(COUNT(B16:H16)=0,"n/a",SUMPRODUCT(B16:H16,Benchmark!$B$4:$H$4)) -> n/a | S16: =IF(COUNT($B16:$H16)=0,0,MMULT($B16:$H16,Inputs!B$26:B$32)) -> 0 | T16: =IF(COUNT($B16:$H16)=0,0,MMULT($B16:$H16,Inputs!C$26:C$32)) -> 0 | U16: =IF(COUNT($B16:$H16)=0,0,MMULT($B16:$H16,Inputs!D$26:D$32)) -> 0 | V16: =IF(COUNT($B16:$H16)=0,0,MMULT($B16:$H16,Inputs!E$26:E$32)) -> 0 | W16: =IF(COUNT($B16:$H16)=0,0,MMULT($B16:$H16,Inputs!F$26:F$32)) -> 0 | X16: =IF(COUNT($B16:$H16)=0,0,MMULT($B16:$H16,Inputs!G$26:G$32)) -> 0 | Y16: =IF(COUNT($B16:$H16)=0,0,MMULT($B16:$H16,Inputs!H$26:H$32)) -> 0
A17: =Strategies!A8 -> Growth | I17: =IF(COUNT(B17:H17)=0,"n/a",SUM(B17:H17)) -> n/a | J17: =IF(COUNT(B17:H17)=0,"n/a",SUMPRODUCT(B17:H17,Benchmark!$B$3:$H$3)) -> n/a | K17: =IF(COUNT(B17:H17)=0,"n/a",SQRT(MAX(SUMPRODUCT(B17:H17,S17:Y17),0))) -> n/a | L17: =IF(COUNT(B17:H17)=0,"n/a",SUMPRODUCT(B17:H17,Benchmark!$B$4:$H$4)) -> n/a | S17: =IF(COUNT($B17:$H17)=0,0,MMULT($B17:$H17,Inputs!B$26:B$32)) -> 0 | T17: =IF(COUNT($B17:$H17)=0,0,MMULT($B17:$H17,Inputs!C$26:C$32)) -> 0 | U17: =IF(COUNT($B17:$H17)=0,0,MMULT($B17:$H17,Inputs!D$26:D$32)) -> 0 | V17: =IF(COUNT($B17:$H17)=0,0,MMULT($B17:$H17,Inputs!E$26:E$32)) -> 0 | W17: =IF(COUNT($B17:$H17)=0,0,MMULT($B17:$H17,Inputs!F$26:F$32)) -> 0 | X17: =IF(COUNT($B17:$H17)=0,0,MMULT($B17:$H17,Inputs!G$26:G$32)) -> 0 | Y17: =IF(COUNT($B17:$H17)=0,0,MMULT($B17:$H17,Inputs!H$26:H$32)) -> 0
A18: =Strategies!A9 -> Income | I18: =IF(COUNT(B18:H18)=0,"n/a",SUM(B18:H18)) -> n/a | J18: =IF(COUNT(B18:H18)=0,"n/a",SUMPRODUCT(B18:H18,Benchmark!$B$3:$H$3)) -> n/a | K18: =IF(COUNT(B18:H18)=0,"n/a",SQRT(MAX(SUMPRODUCT(B18:H18,S18:Y18),0))) -> n/a | L18: =IF(COUNT(B18:H18)=0,"n/a",SUMPRODUCT(B18:H18,Benchmark!$B$4:$H$4)) -> n/a | S18: =IF(COUNT($B18:$H18)=0,0,MMULT($B18:$H18,Inputs!B$26:B$32)) -> 0 | T18: =IF(COUNT($B18:$H18)=0,0,MMULT($B18:$H18,Inputs!C$26:C$32)) -> 0 | U18: =IF(COUNT($B18:$H18)=0,0,MMULT($B18:$H18,Inputs!D$26:D$32)) -> 0 | V18: =IF(COUNT($B18:$H18)=0,0,MMULT($B18:$H18,Inputs!E$26:E$32)) -> 0 | W18: =IF(COUNT($B18:$H18)=0,0,MMULT($B18:$H18,Inputs!F$26:F$32)) -> 0 | X18: =IF(COUNT($B18:$H18)=0,0,MMULT($B18:$H18,Inputs!G$26:G$32)) -> 0 | Y18: =IF(COUNT($B18:$H18)=0,0,MMULT($B18:$H18,Inputs!H$26:H$32)) -> 0
A19: =Strategies!A10 -> Income Plus | I19: =IF(COUNT(B19:H19)=0,"n/a",SUM(B19:H19)) -> n/a | J19: =IF(COUNT(B19:H19)=0,"n/a",SUMPRODUCT(B19:H19,Benchmark!$B$3:$H$3)) -> n/a | K19: =IF(COUNT(B19:H19)=0,"n/a",SQRT(MAX(SUMPRODUCT(B19:H19,S19:Y19),0))) -> n/a | L19: =IF(COUNT(B19:H19)=0,"n/a",SUMPRODUCT(B19:H19,Benchmark!$B$4:$H$4)) -> n/a | S19: =IF(COUNT($B19:$H19)=0,0,MMULT($B19:$H19,Inputs!B$26:B$32)) -> 0 | T19: =IF(COUNT($B19:$H19)=0,0,MMULT($B19:$H19,Inputs!C$26:C$32)) -> 0 | U19: =IF(COUNT($B19:$H19)=0,0,MMULT($B19:$H19,Inputs!D$26:D$32)) -> 0 | V19: =IF(COUNT($B19:$H19)=0,0,MMULT($B19:$H19,Inputs!E$26:E$32)) -> 0 | W19: =IF(COUNT($B19:$H19)=0,0,MMULT($B19:$H19,Inputs!F$26:F$32)) -> 0 | X19: =IF(COUNT($B19:$H19)=0,0,MMULT($B19:$H19,Inputs!G$26:G$32)) -> 0 | Y19: =IF(COUNT($B19:$H19)=0,0,MMULT($B19:$H19,Inputs!H$26:H$32)) -> 0
A20: =Strategies!A11 -> Defensive Responsible | I20: =IF(COUNT(B20:H20)=0,"n/a",SUM(B20:H20)) -> n/a | J20: =IF(COUNT(B20:H20)=0,"n/a",SUMPRODUCT(B20:H20,Benchmark!$B$3:$H$3)) -> n/a | K20: =IF(COUNT(B20:H20)=0,"n/a",SQRT(MAX(SUMPRODUCT(B20:H20,S20:Y20),0))) -> n/a | L20: =IF(COUNT(B20:H20)=0,"n/a",SUMPRODUCT(B20:H20,Benchmark!$B$4:$H$4)) -> n/a | S20: =IF(COUNT($B20:$H20)=0,0,MMULT($B20:$H20,Inputs!B$26:B$32)) -> 0 | T20: =IF(COUNT($B20:$H20)=0,0,MMULT($B20:$H20,Inputs!C$26:C$32)) -> 0 | U20: =IF(COUNT($B20:$H20)=0,0,MMULT($B20:$H20,Inputs!D$26:D$32)) -> 0 | V20: =IF(COUNT($B20:$H20)=0,0,MMULT($B20:$H20,Inputs!E$26:E$32)) -> 0 | W20: =IF(COUNT($B20:$H20)=0,0,MMULT($B20:$H20,Inputs!F$26:F$32)) -> 0 | X20: =IF(COUNT($B20:$H20)=0,0,MMULT($B20:$H20,Inputs!G$26:G$32)) -> 0 | Y20: =IF(COUNT($B20:$H20)=0,0,MMULT($B20:$H20,Inputs!H$26:H$32)) -> 0
A21: =Strategies!A12 -> Cautious Responsible | I21: =IF(COUNT(B21:H21)=0,"n/a",SUM(B21:H21)) -> n/a | J21: =IF(COUNT(B21:H21)=0,"n/a",SUMPRODUCT(B21:H21,Benchmark!$B$3:$H$3)) -> n/a | K21: =IF(COUNT(B21:H21)=0,"n/a",SQRT(MAX(SUMPRODUCT(B21:H21,S21:Y21),0))) -> n/a | L21: =IF(COUNT(B21:H21)=0,"n/a",SUMPRODUCT(B21:H21,Benchmark!$B$4:$H$4)) -> n/a | S21: =IF(COUNT($B21:$H21)=0,0,MMULT($B21:$H21,Inputs!B$26:B$32)) -> 0 | T21: =IF(COUNT($B21:$H21)=0,0,MMULT($B21:$H21,Inputs!C$26:C$32)) -> 0 | U21: =IF(COUNT($B21:$H21)=0,0,MMULT($B21:$H21,Inputs!D$26:D$32)) -> 0 | V21: =IF(COUNT($B21:$H21)=0,0,MMULT($B21:$H21,Inputs!E$26:E$32)) -> 0 | W21: =IF(COUNT($B21:$H21)=0,0,MMULT($B21:$H21,Inputs!F$26:F$32)) -> 0 | X21: =IF(COUNT($B21:$H21)=0,0,MMULT($B21:$H21,Inputs!G$26:G$32)) -> 0 | Y21: =IF(COUNT($B21:$H21)=0,0,MMULT($B21:$H21,Inputs!H$26:H$32)) -> 0
A22: =Strategies!A13 -> Balanced Responsible | I22: =IF(COUNT(B22:H22)=0,"n/a",SUM(B22:H22)) -> n/a | J22: =IF(COUNT(B22:H22)=0,"n/a",SUMPRODUCT(B22:H22,Benchmark!$B$3:$H$3)) -> n/a | K22: =IF(COUNT(B22:H22)=0,"n/a",SQRT(MAX(SUMPRODUCT(B22:H22,S22:Y22),0))) -> n/a | L22: =IF(COUNT(B22:H22)=0,"n/a",SUMPRODUCT(B22:H22,Benchmark!$B$4:$H$4)) -> n/a | S22: =IF(COUNT($B22:$H22)=0,0,MMULT($B22:$H22,Inputs!B$26:B$32)) -> 0 | T22: =IF(COUNT($B22:$H22)=0,0,MMULT($B22:$H22,Inputs!C$26:C$32)) -> 0 | U22: =IF(COUNT($B22:$H22)=0,0,MMULT($B22:$H22,Inputs!D$26:D$32)) -> 0 | V22: =IF(COUNT($B22:$H22)=0,0,MMULT($B22:$H22,Inputs!E$26:E$32)) -> 0 | W22: =IF(COUNT($B22:$H22)=0,0,MMULT($B22:$H22,Inputs!F$26:F$32)) -> 0 | X22: =IF(COUNT($B22:$H22)=0,0,MMULT($B22:$H22,Inputs!G$26:G$32)) -> 0 | Y22: =IF(COUNT($B22:$H22)=0,0,MMULT($B22:$H22,Inputs!H$26:H$32)) -> 0
A23: =Strategies!A14 -> Growth Responsible | I23: =IF(COUNT(B23:H23)=0,"n/a",SUM(B23:H23)) -> n/a | J23: =IF(COUNT(B23:H23)=0,"n/a",SUMPRODUCT(B23:H23,Benchmark!$B$3:$H$3)) -> n/a | K23: =IF(COUNT(B23:H23)=0,"n/a",SQRT(MAX(SUMPRODUCT(B23:H23,S23:Y23),0))) -> n/a | L23: =IF(COUNT(B23:H23)=0,"n/a",SUMPRODUCT(B23:H23,Benchmark!$B$4:$H$4)) -> n/a | S23: =IF(COUNT($B23:$H23)=0,0,MMULT($B23:$H23,Inputs!B$26:B$32)) -> 0 | T23: =IF(COUNT($B23:$H23)=0,0,MMULT($B23:$H23,Inputs!C$26:C$32)) -> 0 | U23: =IF(COUNT($B23:$H23)=0,0,MMULT($B23:$H23,Inputs!D$26:D$32)) -> 0 | V23: =IF(COUNT($B23:$H23)=0,0,MMULT($B23:$H23,Inputs!E$26:E$32)) -> 0 | W23: =IF(COUNT($B23:$H23)=0,0,MMULT($B23:$H23,Inputs!F$26:F$32)) -> 0 | X23: =IF(COUNT($B23:$H23)=0,0,MMULT($B23:$H23,Inputs!G$26:G$32)) -> 0 | Y23: =IF(COUNT($B23:$H23)=0,0,MMULT($B23:$H23,Inputs!H$26:H$32)) -> 0
A24: Example (format only) | B24: 0.147 | C24: 0.296 | D24: 0.179 | E24: 0.047 | F24: 0.044 | G24: 0.097 | H24: 0.19
A25: Example row = starting weights shown for Defensive in the MO's SAA Instructions (147, 296, 179, 47, 44, 97, 190 out of 1,000). Not part of the check.
A27: 2. Weight difference: RISKOptimizer minus Solver (percentage points)
A28: Strategy | B28: Equity | C28: DM Gov | D28: Bonds other | E28: Property | F28: Gold | G28: Hedge funds | H28: Cash | I28: Largest absolute difference | J28: Expected return diff. | K28: Volatility diff. | L28: Benchmark status
A29: =Strategies!A5 -> Defensive | B29: =IF(COUNT($B14:$H14)=0,"n/a",B14-Benchmark!B7) -> n/a | C29: =IF(COUNT($B14:$H14)=0,"n/a",C14-Benchmark!C7) -> n/a | D29: =IF(COUNT($B14:$H14)=0,"n/a",D14-Benchmark!D7) -> n/a | E29: =IF(COUNT($B14:$H14)=0,"n/a",E14-Benchmark!E7) -> n/a | F29: =IF(COUNT($B14:$H14)=0,"n/a",F14-Benchmark!F7) -> n/a | G29: =IF(COUNT($B14:$H14)=0,"n/a",G14-Benchmark!G7) -> n/a | H29: =IF(COUNT($B14:$H14)=0,"n/a",H14-Benchmark!H7) -> n/a | I29: =IF(COUNT($B14:$H14)=0,"n/a",MAX(ABS(B29),ABS(C29),ABS(D29),ABS(E29),ABS(F29),ABS(G29),ABS(H29))) -> n/a | J29: =IF(COUNT($B14:$H14)=0,"n/a",J14-Benchmark!J7) -> n/a | K29: =IF(COUNT($B14:$H14)=0,"n/a",K14-Benchmark!L7) -> n/a | L29: =IF(COUNT($B14:$H14)=0,"n/a",IF(AND(I29<=$M$4,ABS(J29)<=$M$5,ABS(K29)<=$M$6),"PASS","CHECK")) -> n/a
A30: =Strategies!A6 -> Cautious | B30: =IF(COUNT($B15:$H15)=0,"n/a",B15-Benchmark!B8) -> n/a | C30: =IF(COUNT($B15:$H15)=0,"n/a",C15-Benchmark!C8) -> n/a | D30: =IF(COUNT($B15:$H15)=0,"n/a",D15-Benchmark!D8) -> n/a | E30: =IF(COUNT($B15:$H15)=0,"n/a",E15-Benchmark!E8) -> n/a | F30: =IF(COUNT($B15:$H15)=0,"n/a",F15-Benchmark!F8) -> n/a | G30: =IF(COUNT($B15:$H15)=0,"n/a",G15-Benchmark!G8) -> n/a | H30: =IF(COUNT($B15:$H15)=0,"n/a",H15-Benchmark!H8) -> n/a | I30: =IF(COUNT($B15:$H15)=0,"n/a",MAX(ABS(B30),ABS(C30),ABS(D30),ABS(E30),ABS(F30),ABS(G30),ABS(H30))) -> n/a | J30: =IF(COUNT($B15:$H15)=0,"n/a",J15-Benchmark!J8) -> n/a | K30: =IF(COUNT($B15:$H15)=0,"n/a",K15-Benchmark!L8) -> n/a | L30: =IF(COUNT($B15:$H15)=0,"n/a",IF(AND(I30<=$M$4,ABS(J30)<=$M$5,ABS(K30)<=$M$6),"PASS","CHECK")) -> n/a
A31: =Strategies!A7 -> Balanced | B31: =IF(COUNT($B16:$H16)=0,"n/a",B16-Benchmark!B9) -> n/a | C31: =IF(COUNT($B16:$H16)=0,"n/a",C16-Benchmark!C9) -> n/a | D31: =IF(COUNT($B16:$H16)=0,"n/a",D16-Benchmark!D9) -> n/a | E31: =IF(COUNT($B16:$H16)=0,"n/a",E16-Benchmark!E9) -> n/a | F31: =IF(COUNT($B16:$H16)=0,"n/a",F16-Benchmark!F9) -> n/a | G31: =IF(COUNT($B16:$H16)=0,"n/a",G16-Benchmark!G9) -> n/a | H31: =IF(COUNT($B16:$H16)=0,"n/a",H16-Benchmark!H9) -> n/a | I31: =IF(COUNT($B16:$H16)=0,"n/a",MAX(ABS(B31),ABS(C31),ABS(D31),ABS(E31),ABS(F31),ABS(G31),ABS(H31))) -> n/a | J31: =IF(COUNT($B16:$H16)=0,"n/a",J16-Benchmark!J9) -> n/a | K31: =IF(COUNT($B16:$H16)=0,"n/a",K16-Benchmark!L9) -> n/a | L31: =IF(COUNT($B16:$H16)=0,"n/a",IF(AND(I31<=$M$4,ABS(J31)<=$M$5,ABS(K31)<=$M$6),"PASS","CHECK")) -> n/a
A32: =Strategies!A8 -> Growth | B32: =IF(COUNT($B17:$H17)=0,"n/a",B17-Benchmark!B10) -> n/a | C32: =IF(COUNT($B17:$H17)=0,"n/a",C17-Benchmark!C10) -> n/a | D32: =IF(COUNT($B17:$H17)=0,"n/a",D17-Benchmark!D10) -> n/a | E32: =IF(COUNT($B17:$H17)=0,"n/a",E17-Benchmark!E10) -> n/a | F32: =IF(COUNT($B17:$H17)=0,"n/a",F17-Benchmark!F10) -> n/a | G32: =IF(COUNT($B17:$H17)=0,"n/a",G17-Benchmark!G10) -> n/a | H32: =IF(COUNT($B17:$H17)=0,"n/a",H17-Benchmark!H10) -> n/a | I32: =IF(COUNT($B17:$H17)=0,"n/a",MAX(ABS(B32),ABS(C32),ABS(D32),ABS(E32),ABS(F32),ABS(G32),ABS(H32))) -> n/a | J32: =IF(COUNT($B17:$H17)=0,"n/a",J17-Benchmark!J10) -> n/a | K32: =IF(COUNT($B17:$H17)=0,"n/a",K17-Benchmark!L10) -> n/a | L32: =IF(COUNT($B17:$H17)=0,"n/a",IF(AND(I32<=$M$4,ABS(J32)<=$M$5,ABS(K32)<=$M$6),"PASS","CHECK")) -> n/a
A33: =Strategies!A9 -> Income | B33: =IF(COUNT($B18:$H18)=0,"n/a",B18-Benchmark!B11) -> n/a | C33: =IF(COUNT($B18:$H18)=0,"n/a",C18-Benchmark!C11) -> n/a | D33: =IF(COUNT($B18:$H18)=0,"n/a",D18-Benchmark!D11) -> n/a | E33: =IF(COUNT($B18:$H18)=0,"n/a",E18-Benchmark!E11) -> n/a | F33: =IF(COUNT($B18:$H18)=0,"n/a",F18-Benchmark!F11) -> n/a | G33: =IF(COUNT($B18:$H18)=0,"n/a",G18-Benchmark!G11) -> n/a | H33: =IF(COUNT($B18:$H18)=0,"n/a",H18-Benchmark!H11) -> n/a | I33: =IF(COUNT($B18:$H18)=0,"n/a",MAX(ABS(B33),ABS(C33),ABS(D33),ABS(E33),ABS(F33),ABS(G33),ABS(H33))) -> n/a | J33: =IF(COUNT($B18:$H18)=0,"n/a",J18-Benchmark!J11) -> n/a | K33: =IF(COUNT($B18:$H18)=0,"n/a",K18-Benchmark!L11) -> n/a | L33: =IF(COUNT($B18:$H18)=0,"n/a",IF(AND(I33<=$M$4,ABS(J33)<=$M$5,ABS(K33)<=$M$6),"PASS","CHECK")) -> n/a
A34: =Strategies!A10 -> Income Plus | B34: =IF(COUNT($B19:$H19)=0,"n/a",B19-Benchmark!B12) -> n/a | C34: =IF(COUNT($B19:$H19)=0,"n/a",C19-Benchmark!C12) -> n/a | D34: =IF(COUNT($B19:$H19)=0,"n/a",D19-Benchmark!D12) -> n/a | E34: =IF(COUNT($B19:$H19)=0,"n/a",E19-Benchmark!E12) -> n/a | F34: =IF(COUNT($B19:$H19)=0,"n/a",F19-Benchmark!F12) -> n/a | G34: =IF(COUNT($B19:$H19)=0,"n/a",G19-Benchmark!G12) -> n/a | H34: =IF(COUNT($B19:$H19)=0,"n/a",H19-Benchmark!H12) -> n/a | I34: =IF(COUNT($B19:$H19)=0,"n/a",MAX(ABS(B34),ABS(C34),ABS(D34),ABS(E34),ABS(F34),ABS(G34),ABS(H34))) -> n/a | J34: =IF(COUNT($B19:$H19)=0,"n/a",J19-Benchmark!J12) -> n/a | K34: =IF(COUNT($B19:$H19)=0,"n/a",K19-Benchmark!L12) -> n/a | L34: =IF(COUNT($B19:$H19)=0,"n/a",IF(AND(I34<=$M$4,ABS(J34)<=$M$5,ABS(K34)<=$M$6),"PASS","CHECK")) -> n/a
A35: =Strategies!A11 -> Defensive Responsible | B35: =IF(COUNT($B20:$H20)=0,"n/a",B20-Benchmark!B13) -> n/a | C35: =IF(COUNT($B20:$H20)=0,"n/a",C20-Benchmark!C13) -> n/a | D35: =IF(COUNT($B20:$H20)=0,"n/a",D20-Benchmark!D13) -> n/a | E35: =IF(COUNT($B20:$H20)=0,"n/a",E20-Benchmark!E13) -> n/a | F35: =IF(COUNT($B20:$H20)=0,"n/a",F20-Benchmark!F13) -> n/a | G35: =IF(COUNT($B20:$H20)=0,"n/a",G20-Benchmark!G13) -> n/a | H35: =IF(COUNT($B20:$H20)=0,"n/a",H20-Benchmark!H13) -> n/a | I35: =IF(COUNT($B20:$H20)=0,"n/a",MAX(ABS(B35),ABS(C35),ABS(D35),ABS(E35),ABS(F35),ABS(G35),ABS(H35))) -> n/a | J35: =IF(COUNT($B20:$H20)=0,"n/a",J20-Benchmark!J13) -> n/a | K35: =IF(COUNT($B20:$H20)=0,"n/a",K20-Benchmark!L13) -> n/a | L35: =IF(COUNT($B20:$H20)=0,"n/a",IF(AND(I35<=$M$4,ABS(J35)<=$M$5,ABS(K35)<=$M$6),"PASS","CHECK")) -> n/a
A36: =Strategies!A12 -> Cautious Responsible | B36: =IF(COUNT($B21:$H21)=0,"n/a",B21-Benchmark!B14) -> n/a | C36: =IF(COUNT($B21:$H21)=0,"n/a",C21-Benchmark!C14) -> n/a | D36: =IF(COUNT($B21:$H21)=0,"n/a",D21-Benchmark!D14) -> n/a | E36: =IF(COUNT($B21:$H21)=0,"n/a",E21-Benchmark!E14) -> n/a | F36: =IF(COUNT($B21:$H21)=0,"n/a",F21-Benchmark!F14) -> n/a | G36: =IF(COUNT($B21:$H21)=0,"n/a",G21-Benchmark!G14) -> n/a | H36: =IF(COUNT($B21:$H21)=0,"n/a",H21-Benchmark!H14) -> n/a | I36: =IF(COUNT($B21:$H21)=0,"n/a",MAX(ABS(B36),ABS(C36),ABS(D36),ABS(E36),ABS(F36),ABS(G36),ABS(H36))) -> n/a | J36: =IF(COUNT($B21:$H21)=0,"n/a",J21-Benchmark!J14) -> n/a | K36: =IF(COUNT($B21:$H21)=0,"n/a",K21-Benchmark!L14) -> n/a | L36: =IF(COUNT($B21:$H21)=0,"n/a",IF(AND(I36<=$M$4,ABS(J36)<=$M$5,ABS(K36)<=$M$6),"PASS","CHECK")) -> n/a
A37: =Strategies!A13 -> Balanced Responsible | B37: =IF(COUNT($B22:$H22)=0,"n/a",B22-Benchmark!B15) -> n/a | C37: =IF(COUNT($B22:$H22)=0,"n/a",C22-Benchmark!C15) -> n/a | D37: =IF(COUNT($B22:$H22)=0,"n/a",D22-Benchmark!D15) -> n/a | E37: =IF(COUNT($B22:$H22)=0,"n/a",E22-Benchmark!E15) -> n/a | F37: =IF(COUNT($B22:$H22)=0,"n/a",F22-Benchmark!F15) -> n/a | G37: =IF(COUNT($B22:$H22)=0,"n/a",G22-Benchmark!G15) -> n/a | H37: =IF(COUNT($B22:$H22)=0,"n/a",H22-Benchmark!H15) -> n/a | I37: =IF(COUNT($B22:$H22)=0,"n/a",MAX(ABS(B37),ABS(C37),ABS(D37),ABS(E37),ABS(F37),ABS(G37),ABS(H37))) -> n/a | J37: =IF(COUNT($B22:$H22)=0,"n/a",J22-Benchmark!J15) -> n/a | K37: =IF(COUNT($B22:$H22)=0,"n/a",K22-Benchmark!L15) -> n/a | L37: =IF(COUNT($B22:$H22)=0,"n/a",IF(AND(I37<=$M$4,ABS(J37)<=$M$5,ABS(K37)<=$M$6),"PASS","CHECK")) -> n/a
A38: =Strategies!A14 -> Growth Responsible | B38: =IF(COUNT($B23:$H23)=0,"n/a",B23-Benchmark!B16) -> n/a | C38: =IF(COUNT($B23:$H23)=0,"n/a",C23-Benchmark!C16) -> n/a | D38: =IF(COUNT($B23:$H23)=0,"n/a",D23-Benchmark!D16) -> n/a | E38: =IF(COUNT($B23:$H23)=0,"n/a",E23-Benchmark!E16) -> n/a | F38: =IF(COUNT($B23:$H23)=0,"n/a",F23-Benchmark!F16) -> n/a | G38: =IF(COUNT($B23:$H23)=0,"n/a",G23-Benchmark!G16) -> n/a | H38: =IF(COUNT($B23:$H23)=0,"n/a",H23-Benchmark!H16) -> n/a | I38: =IF(COUNT($B23:$H23)=0,"n/a",MAX(ABS(B38),ABS(C38),ABS(D38),ABS(E38),ABS(F38),ABS(G38),ABS(H38))) -> n/a | J38: =IF(COUNT($B23:$H23)=0,"n/a",J23-Benchmark!J16) -> n/a | K38: =IF(COUNT($B23:$H23)=0,"n/a",K23-Benchmark!L16) -> n/a | L38: =IF(COUNT($B23:$H23)=0,"n/a",IF(AND(I38<=$M$4,ABS(J38)<=$M$5,ABS(K38)<=$M$6),"PASS","CHECK")) -> n/a
A40: 3. Constraint check on the RISKOptimizer weights
A41: Strategy | B41: Sum of weights | C41: Bound breaches (count) | D41: Largest bound breach | E41: Volatility | F41: Volatility target | G41: Volatility above target | H41: Yield | I41: Minimum yield | J41: Yield below minimum | K41: Constraint status
A42: =Strategies!A5 -> Defensive | B42: =I14 -> n/a | C42: =IF(COUNT($B14:$H14)=0,"n/a",SUMPRODUCT((B14:H14<Benchmark!B22:H22-$M$7)+(B14:H14>Benchmark!B35:H35+$M$7))) -> n/a | D42: =IF(COUNT($B14:$H14)=0,"n/a",MAX(0,Benchmark!B22-B14,B14-Benchmark!B35,Benchmark!C22-C14,C14-Benchmark!C35,Benchmark!D22-D14,D14-Benchmark!D35,Benchmark!E22-E14,E14-Benchmark!E35,Benchmark!F22-F14,F14-Benchmark!F35,Benchmark!G22-G14,G14-Benchmark!G35,Benchmark!H22-H14,H14-Benchmark!H35)) -> n/a | E42: =K14 -> n/a | F42: =Benchmark!M7 -> 0.0405 | G42: =IF(COUNT($B14:$H14)=0,"n/a",MAX(0,E42-F42)) -> n/a | H42: =L14 -> n/a | I42: =Benchmark!P7 -> 0 | J42: =IF(COUNT($B14:$H14)=0,"n/a",MAX(0,I42-H42)) -> n/a | K42: =IF(COUNT($B14:$H14)=0,"n/a",IF(AND(ABS(B42-1)<0.0001,C42=0,G42<=$M$8,J42<=$M$9),"PASS","CHECK")) -> n/a
A43: =Strategies!A6 -> Cautious | B43: =I15 -> n/a | C43: =IF(COUNT($B15:$H15)=0,"n/a",SUMPRODUCT((B15:H15<Benchmark!B23:H23-$M$7)+(B15:H15>Benchmark!B36:H36+$M$7))) -> n/a | D43: =IF(COUNT($B15:$H15)=0,"n/a",MAX(0,Benchmark!B23-B15,B15-Benchmark!B36,Benchmark!C23-C15,C15-Benchmark!C36,Benchmark!D23-D15,D15-Benchmark!D36,Benchmark!E23-E15,E15-Benchmark!E36,Benchmark!F23-F15,F15-Benchmark!F36,Benchmark!G23-G15,G15-Benchmark!G36,Benchmark!H23-H15,H15-Benchmark!H36)) -> n/a | E43: =K15 -> n/a | F43: =Benchmark!M8 -> 0.0675 | G43: =IF(COUNT($B15:$H15)=0,"n/a",MAX(0,E43-F43)) -> n/a | H43: =L15 -> n/a | I43: =Benchmark!P8 -> 0 | J43: =IF(COUNT($B15:$H15)=0,"n/a",MAX(0,I43-H43)) -> n/a | K43: =IF(COUNT($B15:$H15)=0,"n/a",IF(AND(ABS(B43-1)<0.0001,C43=0,G43<=$M$8,J43<=$M$9),"PASS","CHECK")) -> n/a
A44: =Strategies!A7 -> Balanced | B44: =I16 -> n/a | C44: =IF(COUNT($B16:$H16)=0,"n/a",SUMPRODUCT((B16:H16<Benchmark!B24:H24-$M$7)+(B16:H16>Benchmark!B37:H37+$M$7))) -> n/a | D44: =IF(COUNT($B16:$H16)=0,"n/a",MAX(0,Benchmark!B24-B16,B16-Benchmark!B37,Benchmark!C24-C16,C16-Benchmark!C37,Benchmark!D24-D16,D16-Benchmark!D37,Benchmark!E24-E16,E16-Benchmark!E37,Benchmark!F24-F16,F16-Benchmark!F37,Benchmark!G24-G16,G16-Benchmark!G37,Benchmark!H24-H16,H16-Benchmark!H37)) -> n/a | E44: =K16 -> n/a | F44: =Benchmark!M9 -> 0.0945 | G44: =IF(COUNT($B16:$H16)=0,"n/a",MAX(0,E44-F44)) -> n/a | H44: =L16 -> n/a | I44: =Benchmark!P9 -> 0 | J44: =IF(COUNT($B16:$H16)=0,"n/a",MAX(0,I44-H44)) -> n/a | K44: =IF(COUNT($B16:$H16)=0,"n/a",IF(AND(ABS(B44-1)<0.0001,C44=0,G44<=$M$8,J44<=$M$9),"PASS","CHECK")) -> n/a
...

Sheet Run_Log
A1: Run log – Solver benchmark
A2: Add one row per strategy with a CHECK result (or one row per annual run if everything passes).
A4: Date | B4: Run by | C4: Reviewed by | D4: Strategy | E4: Benchmark status | F4: Constraint status | G4: Difference beyond tolerance | H4: Explanation | I4: Action taken | J4: Sign-off
A5: dd/mm/yyyy | B5: Analyst name | C5: Reviewer name | D5: Balanced | E5: CHECK | F5: PASS | G5: Equity 1.4 pp higher than Solver | H5: e.g. RISKOptimizer volatility measured on simulated paths; vol 0.03 pp above target, within tolerance | I5: Accepted; re-run with 1,000 iterations gave same result | J5: Reviewer initials
A6: (example row above – format only)
